Workbook
Name _PG1: #REF!
Name _PG3: #REF!
Name _Regression_Int: 1
Name \p: #REF!
Name Advanced: #REF!
Name Alphabet: #REF!
Name Bank: #REF!
Name Canada: #REF!
Name Catagory: #REF!
Name Check: #REF!
Name code: #REF!
Name Construction_Contingency: #REF!
Name d: #REF!
Name details_14: #REF!
Name details_21: #REF!
Name details_30: #REF!
Name details_60: #REF!
Name details_7: #REF!
Name details_past: #REF!
Name Electrical_Vault: #REF!
Name Escalation: #REF!
Name GRAND: 'G703'!$A$77
Name HardCost: #REF!
Name IndirectHardCost: #REF!
Name Invoice_Detail_Amount: #REF!
Name Invoice_Detail_Approved: #REF!
Name Invoice_Detail_Code: #REF!
Name Invoice_Detail_Draw: #REF!
Name InvoiceDetail_Notes: #REF!
Name Loan_Detail_Mat_Due_14: #REF!
Name Loan_Detail_Mat_Due_21: #REF!
Name Loan_Detail_Mat_Due_30: #REF!
Name Loan_Detail_Mat_Due_60: #REF!
Name Loan_Detail_Mat_Due_7: #REF!
Name Loan_Detail_Mat_Past_Due: #REF!
Name Phase: #REF!
Name Print_Area_MI: '702'!$A$3:$I$34
Name Print_Titles_MI: '702'!$47:$354,'702'!$B:$CV
Name PRLOANTHREE: #REF!
Name PROPDATATHREE: #REF!
Name Reall_Amount: #REF!
Name Reall_Amt: #REF!
Name Reall_Approved: #REF!
Name Reall_Code: #REF!
Name Reall_Draw: #REF!
Name Reall_Num: #REF!
Name s: #REF!
Name Service_Provider: #REF!
Name SoftCost: #REF!
Name Spacialties: #REF!
Name Status_Summary_Coding: #REF!
Name tax_14: #REF!
Name tax_21: #REF!
Name tax_30: #REF!
Name tax_60: #REF!
Name tax_7: #REF!
Name tax_past: #REF!
Name Temporary_Fence: #REF!
Name Tenant_Improvement: #REF!
Name Testing_and_Inspection: #REF!

Sheet 702
A3: Application for Payment
A5: GENERAL CONTRACTOR | E5: PROJECT: | G5: ='Prelim Sheet'!F29
A6: ='Prelim Sheet'!F14
A7: ='Prelim Sheet'!F15 | E7: PROJECT #: | G7: ='G703'!I3
A8: ='Prelim Sheet'!F16
A9: Billing@712seagaze.com | E9: INVOICE #: | G9: ='G703'!I2
A11: FROM SUB-CONTRACTOR: | E11: INVOICE DATE: | G11: ='G703'!I4
A12: Ferrocrete Builders, Inc
A13: 440 Western Ave Suite 203 | E13: INVOICE THROUGH: | G13: ='G703'!I5
A14: Glendale, CA 91201
A17: CONTRACTOR'S APPLICATION FOR PAYMENT
A18: Application is made for payment, as shown below, in connection with the Contract.
A19: Continuation Sheet, is attached.
A22: 1. ORIGINAL CONTRACT SUM | F22: $ | G22: =SUM('G703'!C15:C72)
A23: 2. CHANGE ORDERS | F23: $ | G23: =SUM('G703'!C74:C76)
A24: 3. REVISED CONTRACT SUM | F24: $ | G24: =G23+G22
A26: 4. TOTAL COMPLETED & STORED TO DATE (Column G on attached sheet) | F26: $ | G26: ='G703'!G78
A27: 5. RETAINAGE: | C27: 0.1 | F27: $ | G27: ='G703'!J78
A28: 6. TOTAL EARNED LESS RETAINAGE | F28: $ | G28: =G26-G27
A29: 7. LESS PREVIOUS CERTIFICATES FOR PAYMENT (Line 6 from prior app) | F29: $ | G29: =(1-C27)*'G703'!D78
A30: 8. CURRENT PAYMENT DUE (Current gross less current retainage) | F30: $ | G30: =G28-G29
A31: 9. BALANCE TO FINISH, INCLUDING RETAINAGE | F31: $ | G31: =G24-G28
A35: The undersigned Subcontractor certifies that to the best of the Subcontractor's knowledge,
A36: information and belief the Work covered by this Application for Payment has been
A37: completed in accordance with the Contract Documents, that all amounts have been paid by
A38: the Contractor for Work for which previous Certificates for Payment were issued and
A39: payments received from the Owner, and that current payment shown herein is now due.
A41: SUBCONTRACTOR
A43: By: | E43: Date: | G43: ='G703'!I4

Sheet G703
A1: CONTINUATION SHEET | I1: PAGE TWO OF TWO PAGES | IH1: /WGPD
H2: APPLICATION NO: | I2: 6 | IH2: /wir.{d 25}~{r 6}/cf~~{L 6}~
H3: PROJECT NO: | I3: 25-05 | IH3: /wgpe
H4: APPLICATION DATE: | I4: 4/27/2026 | IH4: /ru.{d 26}
H5: PERIOD TO: | I5: 4/30/2026 | IH5: {L 5}
IH6: {L 9}
A7: A | B7: B | C7: C | D7: D | E7: E | F7: F | G7: G | I7: H | IH7: /ru.{d 26}~
A8: LEVEL | B8: DESCRIPTION OF WORK | C8: SCHEDULED VALUE | D8: WORK COMPLETED | F8: MATERIALS | G8: TOTAL | H8: % (G + C) | I8: BALANCE TO FINISH (C - G) | J8: Retention
F9: PRESENTLY | G9: COMPLETED
D10: FROM PREVIOUS APPLICATION | E10: THIS PERIOD | F10: STORED | G10: AND STORED
F11: (NOT IN | G11: TO DATE
F12: D OR E) | G12: (D+E+F)
A14: Contract Scope
B15: Mobilization | C15: 50000 | D15: 50000 | G15: =IF(D15+E15+F15=0,"",D15+E15+F15) | H15: =IF(G15=0,"",IF(ISERR(G15/C15),"",G15/C15)) | I15: =IF(C15-G15=0,"",C15-G15) | J15: =G15*'702'!$C$27
B16: Shop Drawings | C16: 45000 | D16: 45000 | G16: =IF(D16+E16+F16=0,"",D16+E16+F16) | H16: =IF(G16=0,"",IF(ISERR(G16/C16),"",G16/C16)) | I16: =IF(C16-G16=0,"",C16-G16) | J16: =G16*'702'!$C$27
B17: Column Forms | C17: 30000 | D17: 30000 | G17: =IF(D17+E17+F17=0,"",D17+E17+F17) | H17: =IF(G17=0,"",IF(ISERR(G17/C17),"",G17/C17)) | I17: =IF(C17-G17=0,"",C17-G17) | J17: =G17*'702'!$C$27
B18: Wall Forms | C18: 40000 | D18: 40000 | G18: =IF(D18+E18+F18=0,"",D18+E18+F18) | H18: =IF(G18=0,"",IF(ISERR(G18/C18),"",G18/C18)) | I18: =IF(C18-G18=0,"",C18-G18) | J18: =G18*'702'!$C$27
B19: Deck Forms | C19: 65000 | D19: 65000 | G19: =IF(D19+E19+F19=0,"",D19+E19+F19) | H19: =IF(G19=0,"",IF(ISERR(G19/C19),"",G19/C19)) | I19: =IF(C19-G19=0,"",C19-G19) | J19: =G19*'702'!$C$27
G20: =IF(D20+E20+F20=0,"",D20+E20+F20) | H20: =IF(G20=0,"",IF(ISERR(G20/C20),"",G20/C20)) | I20: =IF(C20-G20=0,"",C20-G20) | J20: =G20*'702'!$C$27
A21: B3 | B21: Footings - Layout, Trench Compact | C21: 100000 | D21: 100000 | G21: =IF(D21+E21+F21=0,"",D21+E21+F21) | H21: =IF(G21=0,"",IF(ISERR(G21/C21),"",G21/C21)) | I21: =IF(C21-G21=0,"",C21-G21) | J21: =G21*'702'!$C$27
A22: B3 | B22: Footings - Reinforcing | C22: 165000 | D22: 165000 | G22: =IF(D22+E22+F22=0,"",D22+E22+F22) | H22: =IF(G22=0,"",IF(ISERR(G22/C22),"",G22/C22)) | I22: =IF(C22-G22=0,"",C22-G22) | J22: =G22*'702'!$C$27
A23: B3 | B23: Footings - Pour | C23: 460000 | D23: 460000 | G23: =IF(D23+E23+F23=0,"",D23+E23+F23) | H23: =IF(G23=0,"",IF(ISERR(G23/C23),"",G23/C23)) | I23: =IF(C23-G23=0,"",C23-G23) | J23: =G23*'702'!$C$27
A24: B3 | B24: Columns - Reinforcing | C24: 26000 | D24: 26000 | G24: =IF(D24+E24+F24=0,"",D24+E24+F24) | H24: =IF(G24=0,"",IF(ISERR(G24/C24),"",G24/C24)) | I24: =IF(C24-G24=0,"",C24-G24) | J24: =G24*'702'!$C$27
A25: B3 | B25: Columns - Form & Pour | C25: 30000 | D25: 30000 | G25: =IF(D25+E25+F25=0,"",D25+E25+F25) | H25: =IF(G25=0,"",IF(ISERR(G25/C25),"",G25/C25)) | I25: =IF(C25-G25=0,"",C25-G25) | J25: =G25*'702'!$C$27
A26: B3 | B26: CIP/Shotcrete Walls - Reinforcing | C26: 41250 | D26: 41250 | G26: =IF(D26+E26+F26=0,"",D26+E26+F26) | H26: =IF(G26=0,"",IF(ISERR(G26/C26),"",G26/C26)) | I26: =IF(C26-G26=0,"",C26-G26) | J26: =G26*'702'!$C$27
A27: B3 | B27: CIP/Shotcrete Walls - Form & Pour | C27: 240000 | D27: 240000 | G27: =IF(D27+E27+F27=0,"",D27+E27+F27) | H27: =IF(G27=0,"",IF(ISERR(G27/C27),"",G27/C27)) | I27: =IF(C27-G27=0,"",C27-G27) | J27: =G27*'702'!$C$27
A28: B3 | B28: SOG - Fine Grade - Sand and Vapor Barrier | C28: 50000 | D28: 50000 | G28: =IF(D28+E28+F28=0,"",D28+E28+F28) | H28: =IF(G28=0,"",IF(ISERR(G28/C28),"",G28/C28)) | I28: =IF(C28-G28=0,"",C28-G28) | J28: =G28*'702'!$C$27
A29: B3 | B29: SOG - Reinforcing | C29: 20000 | D29: 20000 | G29: =IF(D29+E29+F29=0,"",D29+E29+F29) | H29: =IF(G29=0,"",IF(ISERR(G29/C29),"",G29/C29)) | I29: =IF(C29-G29=0,"",C29-G29) | J29: =G29*'702'!$C$27
A30: B3 | B30: SOG - Pour & Sawcut | C30: 150000 | D30: 150000 | G30: =IF(D30+E30+F30=0,"",D30+E30+F30) | H30: =IF(G30=0,"",IF(ISERR(G30/C30),"",G30/C30)) | I30: =IF(C30-G30=0,"",C30-G30) | J30: =G30*'702'!$C$27
G31: =IF(D31+E31+F31=0,"",D31+E31+F31) | H31: =IF(G31=0,"",IF(ISERR(G31/C31),"",G31/C31)) | I31: =IF(C31-G31=0,"",C31-G31) | J31: =G31*'702'!$C$27
A32: B2 | B32: Deck - Forming | C32: 75000 | D32: 75000 | G32: =IF(D32+E32+F32=0,"",D32+E32+F32) | H32: =IF(G32=0,"",IF(ISERR(G32/C32),"",G32/C32)) | I32: =IF(C32-G32=0,"",C32-G32) | J32: =G32*'702'!$C$27
A33: B2 | B33: Deck - Reinforcing | C33: 76000 | D33: 76000 | G33: =IF(D33+E33+F33=0,"",D33+E33+F33) | H33: =IF(G33=0,"",IF(ISERR(G33/C33),"",G33/C33)) | I33: =IF(C33-G33=0,"",C33-G33) | J33: =G33*'702'!$C$27
A34: B2 | B34: Deck - Pour | C34: 175000 | D34: 175000 | G34: =IF(D34+E34+F34=0,"",D34+E34+F34) | H34: =IF(G34=0,"",IF(ISERR(G34/C34),"",G34/C34)) | I34: =IF(C34-G34=0,"",C34-G34) | J34: =G34*'702'!$C$27
A35: B2 | B35: Columns - Reinforcing | C35: 20000 | D35: 20000 | G35: =IF(D35+E35+F35=0,"",D35+E35+F35) | H35: =IF(G35=0,"",IF(ISERR(G35/C35),"",G35/C35)) | I35: =IF(C35-G35=0,"",C35-G35) | J35: =G35*'702'!$C$27
A36: B2 | B36: Columns - Form & Pour | C36: 25000 | D36: 25000 | G36: =IF(D36+E36+F36=0,"",D36+E36+F36) | H36: =IF(G36=0,"",IF(ISERR(G36/C36),"",G36/C36)) | I36: =IF(C36-G36=0,"",C36-G36) | J36: =G36*'702'!$C$27
A37: B2 | B37: CIP/Shotcrete Walls - Reinforcing | C37: 35000 | D37: 35000 | G37: =IF(D37+E37+F37=0,"",D37+E37+F37) | H37: =IF(G37=0,"",IF(ISERR(G37/C37),"",G37/C37)) | I37: =IF(C37-G37=0,"",C37-G37) | J37: =G37*'702'!$C$27
A38: B2 | B38: CIP/Shotcrete Walls - Form & Pour | C38: 225000 | D38: 225000 | G38: =IF(D38+E38+F38=0,"",D38+E38+F38) | H38: =IF(G38=0,"",IF(ISERR(G38/C38),"",G38/C38)) | I38: =IF(C38-G38=0,"",C38-G38) | J38: =G38*'702'!$C$27
G39: =IF(D39+E39+F39=0,"",D39+E39+F39) | H39: =IF(G39=0,"",IF(ISERR(G39/C39),"",G39/C39)) | I39: =IF(C39-G39=0,"",C39-G39) | J39: =G39*'702'!$C$27
A40: B1 | B40: Deck - Forming | C40: 75000 | D40: 71250 | G40: =IF(D40+E40+F40=0,"",D40+E40+F40) | H40: =IF(G40=0,"",IF(ISERR(G40/C40),"",G40/C40)) | I40: =IF(C40-G40=0,"",C40-G40) | J40: =G40*'702'!$C$27
A41: B1 | B41: Deck - Reinforcing | C41: 76000 | G41: =IF(D41+E41+F41=0,"",D41+E41+F41) | H41: =IF(G41=0,"",IF(ISERR(G41/C41),"",G41/C41)) | I41: =IF(C41-G41=0,"",C41-G41) | J41: =G41*'702'!$C$27
...

Sheet CP
A1: CONDITIONAL WAIVER AND RELEASE ON PROGRESS PAYMENT
A2: NOTICE: THIS DOCUMENT WAIVES THE CLAIMANT'S LIEN, STOP PAYMENT NOTICE, AND PAYMENT BOND RIGHTS EFFECTIVE ON RECEIPT OF PAYMENT. A PERSON SHOULD NOT RELY ON THIS DOCUMENT UNLESS SATISFIED THAT THE CLAIMANT HAS RECEIVED PAYMENT.
A3: Identifying Information
A4: Name of Claimant: | D4: ='Prelim Sheet'!F19
A5: Name of Customer: | D5: ='Prelim Sheet'!F14
A6: Job Location: | C6: ='Prelim Sheet'!F30&'Prelim Sheet'!F31
A7: Owner: | B7: ='Prelim Sheet'!F9
A8: Through Date: | C8: ='G703'!I5
A10: Conditional Waiver and Release
A11: This document waives and releases lien, stop payment notice, and payment bond rights the claimant has for labor and service provided, and equipment and material delivered, to the customer on this job through the Through Date of this document. Rights based upon labor or service provided, or equipment or material delivered, pursuant to a written change order that has been fully executed by the parties prior to the date that this document is signed by the claimant, are waived and released by this document, unless listed as an Exception below. This document is effective only on the claimant's receipt of payment from the financial institution on which the following check is drawn:
A12: Maker of Check: | C12: =D5
A13: Amount of Check: | D13: ='702'!G30
A14: Check Payable to: | D14: =D4
A16: Exceptions
A17: This document does not affect any of the following: (1) Retentions. (2) Extras for which the claimant has not received payment. (3) The following progress payments for which the claimant has previously given a conditional waiver and release but has not received payment:
B18: Date(s) of waiver and release:
B19: Amount(s) of unpaid progress payment(s):
A20: (4) Contract rights, including (A) a right based on rescission, abandonment, or breach of contract, and (B) the right to recover compensation for work not compensated by the payment.
A22: Signature
A23: Claimant's Signature:
A24: Claimant's Title: | D24: Project Executive
A25: Date of Signature: | D25: ='G703'!I4

Sheet UP
A1: UNCONDITIONAL WAIVER AND RELEASE ON PROGRESS PAYMENT
A2: NOTICE TO CLAIMANT: THIS DOCUMENT WAIVES AND RELEASES LIEN, STOP PAYMENT NOTICE, AND PAYMENT BOND RIGHTS UNCONDITIONALLY AND STATES THAT YOU HAVE BEEN PAID FOR GIVING UP THOSE RIGHTS. THIS DOCUMENT IS ENFORCEABLE AGAINST YOU IF YOU SIGN IT, EVEN IF YOU HAVE NOT BEEN PAID. IF YOU HAVE NOT BEEN PAID, USE A CONDITIONAL WAIVER AND RELEASE FORM.
A3: Identifying Information
A4: Name of Claimant: | D4: =CP!D4
A5: Name of Customer: | D5: =CP!D5
A6: Job Location: | C6: =CP!C6
A7: Owner: | B7: =CP!B7
A8: Through Date: | C8: =CP!C8
A10: Unconditional Waiver and Release
A11: This document waives and releases lien, stop payment notice, and payment bond rights the claimant has for labor and service provided, and equipment and material delivered, to the customer on this job through the Through Date of this document. Rights based upon labor or service provided, or equipment or material delivered, pursuant to a written change order that has been fully executed by the parties prior to the date that this document is signed by the claimant, are waived and released by this document, unless listed as an Exception below. The claimant has received the following progress payment:
A12: $ | C12: ='702'!G30
A15: Exceptions
A16: This document does not affect any of the following: (1) Retentions. (2) Extras for which the claimant has not received payment. (3) Contract rights, including (A) a right based on rescission, abandonment, or breach of contract, and (B) the right to recover compensation for work not compensated by the payment.
A18: Signature
A19: Claimant's Signature:
A20: Claimant's Title: | D20: =CP!D24
A21: Date of Signature: | D21: ='G703'!I4

Sheet CF
A1: CONDITIONAL WAIVER AND RELEASE ON FINAL PAYMENT
A2: NOTICE: THIS DOCUMENT WAIVES THE CLAIMANT'S LIEN, STOP PAYMENT NOTICE, AND PAYMENT BOND RIGHTS EFFECTIVE ON RECEIPT OF PAYMENT. A PERSON SHOULD NOT RELY ON THIS DOCUMENT UNLESS SATISFIED THAT THE CLAIMANT HAS RECEIVED PAYMENT.
A3: Identifying Information
A4: Name of Claimant: | D4: =CP!D4
A5: Name of Customer: | D5: =CP!D5
A6: Job Location: | C6: =CP!C6
A7: Owner: | B7: =CP!B7
A9: Conditional Waiver and Release
A10: This document waives and releases lien, stop payment notice, and payment bond rights the claimant has for labor and service provided, and equipment and material delivered, to the customer on this job. Rights based upon labor or service provided, or equipment or material delivered, pursuant to a written change order that has been fully executed by the parties prior to the date that this document is signed by the claimant, are waived and released by this document, unless listed as an Exception below. This document is effective only on the claimant's receipt of payment from the financial institution on which the following check is drawn:
A11: Maker of Check: | C11: =D5
A12: Amount of Check: | D12: ='702'!G30
A13: Check Payable to: | D13: =D4
A15: Exceptions
A16: This document does not affect any of the following:
A17: Disputed claims for extras in the amount of: $
A19: Signature
A20: Claimant's Signature:
A21: Claimant's Title: | D21: Project Executive
A22: Date of Signature:

Sheet UF
A1: UNCONDITIONAL WAIVER AND RELEASE ON FINAL PAYMENT
A2: NOTICE TO CLAIMANT: THIS DOCUMENT WAIVES AND RELEASES LIEN, STOP PAYMENT NOTICE, AND PAYMENT BOND RIGHTS UNCONDITIONALLY AND STATES THAT YOU HAVE BEEN PAID FOR GIVING UP THOSE RIGHTS. THIS DOCUMENT IS ENFORCEABLE AGAINST YOU IF YOU SIGN IT, EVEN IF YOU HAVE NOT BEEN PAID. IF YOU HAVE NOT BEEN PAID, USE A CONDITIONAL WAIVER AND RELEASE FORM.
A3: Identifying Information
A4: Name of Claimant: | D4: =CP!D4
A5: Name of Customer: | D5: =CP!D5
A6: Job Location: | C6: =CP!C6
A7: Owner: | B7: =CP!B7
A9: Unconditional Waiver and Release
A10: This document waives and releases lien, stop payment notice, and payment bond rights the claimant has for all labor and service provided, and equipment and material delivered, to the customer on this job. Rights based upon labor or service provided, or equipment or material delivered, pursuant to a written change order that has been fully executed by the parties prior to the date that this document is signed by the claimant, are waived and released by this document, unless listed as an Exception below. The claimant has been paid in full.
A12: Exceptions
A13: This document does not affect any of the following:
A14: Disputed claims for extras in the amount of: $
A16: Signature
A17: Claimant's Signature:
A18: Claimant's Title: | D18: =CP!D24
A19: Date of Signature:

Sheet Prelim Sheet
A3: Preliminary Job Information
A9: Owner: | F9: 716 Seagaze Affordable LP
F10: Address
F11: City, State Zip
A14: General Contractor: | F14: Prime Built, LLC
F15: 2021 Vanesta Pl A,
F16: Manhattan, KS 66503
A19: Subcontractor: | F19: Ferrocrete Builders, Inc.
F20: 440 Western Ave. Suite 203
F21: Glendale, CA 91204
A24: Lender: | F24: N/A
A29: Job: | F29: 712 Seagaze
F30: 712 Seagaze Dr.
F31: Oceanside, CA 92054
A34: Job Description: | F34: Ferrocrete Builders, Inc., to furnish complete.
F35: materials and labor services to complete the
F36: structural concrete and masonry work at the
F37: address listed above.
